<sdf version='1.7'>
  <world name='default'>
    <light name='sun' type='directional'>
      <cast_shadows>1</cast_shadows>
      <pose>0 0 10 0 -0 0</pose>
      <diffuse>0.8 0.8 0.8 1</diffuse>
      <specular>0.2 0.2 0.2 1</specular>
      <attenuation>
        <range>1000</range>
        <constant>0.9</constant>
        <linear>0.01</linear>
        <quadratic>0.001</quadratic>
      </attenuation>
      <direction>-0.5 0.1 -0.9</direction>
      <spot>
        <inner_angle>0</inner_angle>
        <outer_angle>0</outer_angle>
        <falloff>0</falloff>
      </spot>
    </light>
    <model name='ground_plane'>
      <static>1</static>
      <link name='link'>
        <collision name='collision'>
          <geometry>
            <plane>
              <normal>0 0 1</normal>
              <size>100 100</size>
            </plane>
          </geometry>
          <surface>
            <friction>
              <ode>
                <mu>100</mu>
                <mu2>50</mu2>
              </ode>
              <torsional>
                <ode/>
              </torsional>
            </friction>
            <contact>
              <ode/>
            </contact>
            <bounce/>
          </surface>
          <max_contacts>10</max_contacts>
        </collision>
        <visual name='visual'>
          <cast_shadows>0</cast_shadows>
          <geometry>
            <plane>
              <normal>0 0 1</normal>
              <size>100 100</size>
            </plane>
          </geometry>
          <material>
            <script>
              <uri>file://media/materials/scripts/gazebo.material</uri>
              <name>Gazebo/Grey</name>
            </script>
          </material>
        </visual>
        <self_collide>0</self_collide>
        <enable_wind>0</enable_wind>
        <kinematic>0</kinematic>
      </link>
    </model>
    <gravity>0 0 -9.8</gravity>
    <magnetic_field>6e-06 2.3e-05 -4.2e-05</magnetic_field>
    <atmosphere type='adiabatic'/>
    <physics type='ode'>
      <max_step_size>0.001</max_step_size>
      <real_time_factor>1</real_time_factor>
      <real_time_update_rate>1000</real_time_update_rate>
    </physics>
    <scene>
      <ambient>0.4 0.4 0.4 1</ambient>
      <background>0.7 0.7 0.7 1</background>
      <shadows>1</shadows>
    </scene>
    <wind/>
    <spherical_coordinates>
      <surface_model>EARTH_WGS84</surface_model>
      <latitude_deg>0</latitude_deg>
      <longitude_deg>0</longitude_deg>
      <elevation>0</elevation>
      <heading_deg>0</heading_deg>
    </spherical_coordinates>
    <model name='cafe'>
      <static>1</static>
      <link name='link'>
        <collision name='main_floor'>
          <pose>-0.4 -0.75 0.0948 0 -0 0</pose>
          <geometry>
            <box>
              <size>9.38 22.63 0.19</size>
            </box>
          </geometry>
          <max_contacts>10</max_contacts>
          <surface>
            <contact>
              <ode/>
            </contact>
            <bounce/>
            <friction>
              <torsional>
                <ode/>
              </torsional>
              <ode/>
            </friction>
          </surface>
        </collision>
        <collision name='wall_1'>
          <pose>-5.03 0.53 1.415 0 -0 0</pose>
          <geometry>
            <box>
              <size>0.12 23.16 2.83</size>
            </box>
          </geometry>
          <max_contacts>10</max_contacts>
          <surface>
            <contact>
              <ode/>
            </contact>
            <bounce/>
            <friction>
              <torsional>
                <ode/>
              </torsional>
              <ode/>
            </friction>
          </surface>
        </collision>
        <collision name='wall_2'>
          <pose>4.24 -0.31 1.415 0 -0 0</pose>
          <geometry>
            <box>
              <size>0.12 21.48 2.83</size>
            </box>
          </geometry>
          <max_contacts>10</max_contacts>
          <surface>
            <contact>
              <ode/>
            </contact>
            <bounce/>
            <friction>
              <torsional>
                <ode/>
              </torsional>
              <ode/>
            </friction>
          </surface>
        </collision>
        <collision name='wall_3'>
          <pose>-1.48 7.43 1.415 0 -0 0</pose>
          <geometry>
            <box>
              <size>7.2 0.12 2.83</size>
            </box>
          </geometry>
          <max_contacts>10</max_contacts>
          <surface>
            <contact>
              <ode/>
            </contact>
            <bounce/>
            <friction>
              <torsional>
                <ode/>
              </torsional>
              <ode/>
            </friction>
          </surface>
        </collision>
        <collision name='wall_4'>
          <pose>2.09 8.9 1.435 0 -0 0</pose>
          <geometry>
            <box>
              <size>0.12 3.05 2.87</size>
            </box>
          </geometry>
          <max_contacts>10</max_contacts>
          <surface>
            <contact>
              <ode/>
            </contact>
            <bounce/>
            <friction>
              <torsional>
                <ode/>
              </torsional>
              <ode/>
            </friction>
          </surface>
        </collision>
        <collision name='wall_5'>
          <pose>3.155 10.4 1.435 0 -0 0</pose>
          <geometry>
            <box>
              <size>2.13 0.12 2.87</size>
            </box>
          </geometry>
          <max_contacts>10</max_contacts>
          <surface>
            <contact>
              <ode/>
            </contact>
            <bounce/>
            <friction>
              <torsional>
                <ode/>
              </torsional>
              <ode/>
            </friction>
          </surface>
        </collision>
        <collision name='wall_6'>
          <pose>0.615 -10.98 1.415 0 -0 0</pose>
          <geometry>
            <box>
              <size>7.36 0.15 2.83</size>
            </box>
          </geometry>
          <max_contacts>10</max_contacts>
          <surface>
            <contact>
              <ode/>
            </contact>
            <bounce/>
            <friction>
              <torsional>
                <ode/>
              </torsional>
              <ode/>
            </friction>
          </surface>
        </collision>
        <collision name='wall_7'>
          <pose>-4.62 -10.98 1.415 0 -0 0</pose>
          <geometry>
            <box>
              <size>0.93 0.15 2.83</size>
            </box>
          </geometry>
          <max_contacts>10</max_contacts>
          <surface>
            <contact>
              <ode/>
            </contact>
            <bounce/>
            <friction>
              <torsional>
                <ode/>
              </torsional>
              <ode/>
            </friction>
          </surface>
        </collision>
        <collision name='wall_8'>
          <pose>-3.61 -10.98 2.69 0 -0 0</pose>
          <geometry>
            <box>
              <size>1.09 0.15 0.28</size>
            </box>
          </geometry>
          <max_contacts>10</max_contacts>
          <surface>
            <contact>
              <ode/>
            </contact>
            <bounce/>
            <friction>
              <torsional>
                <ode/>
              </torsional>
              <ode/>
            </friction>
          </surface>
        </collision>
        <collision name='coke'>
          <pose>-4.385 0.26 0.95 0 -0 0</pose>
          <geometry>
            <box>
              <size>1.03 1.03 1.52</size>
            </box>
          </geometry>
          <max_contacts>10</max_contacts>
          <surface>
            <contact>
              <ode/>
            </contact>
            <bounce/>
            <friction>
              <torsional>
                <ode/>
              </torsional>
              <ode/>
            </friction>
          </surface>
        </collision>
        <visual name='visual'>
          <geometry>
            <mesh>
              <uri>model://cafe/meshes/cafe.dae</uri>
            </mesh>
          </geometry>
        </visual>
        <self_collide>0</self_collide>
        <enable_wind>0</enable_wind>
        <kinematic>0</kinematic>
      </link>
      <pose>2.9968 -2.18548 0 0 -0 0</pose>
    </model>
    <model name='milk'>
      <link name='box_body'>
        <pose>0 0 0 0 -0 0</pose>
        <inertial>
          <pose>0 0 0 0 -0 0</pose>
          <mass>1</mass>
          <inertia>
            <ixx>1</ixx>
            <ixy>0</ixy>
            <ixz>0</ixz>
            <iyy>1</iyy>
            <iyz>0</iyz>
            <izz>1</izz>
          </inertia>
        </inertial>
        <self_collide>0</self_collide>
        <kinematic>0</kinematic>
        <visual name='box_body_visual'>
          <pose>0 0 0 0 -0 1.5708</pose>
          <geometry>
            <mesh>
              <scale>1 1 1</scale>
              <uri>model://milk/meshes/model.dae</uri>
            </mesh>
          </geometry>
          <cast_shadows>1</cast_shadows>
          <transparency>0</transparency>
        </visual>
        <collision name='box_body_collision'>
          <laser_retro>0</laser_retro>
          <max_contacts>10</max_contacts>
          <pose>0 0 0.1 0 -0 0</pose>
          <geometry>
            <box>
              <size>0.06 0.095 0.2</size>
            </box>
          </geometry>
          <surface>
            <friction>
              <ode>
                <mu>1</mu>
                <mu2>1</mu2>
                <fdir1>0 0 0</fdir1>
                <slip1>0</slip1>
                <slip2>0</slip2>
              </ode>
              <torsional>
                <coefficient>1</coefficient>
                <patch_radius>0</patch_radius>
                <surface_radius>0</surface_radius>
                <use_patch_radius>1</use_patch_radius>
                <ode>
                  <slip>0</slip>
                </ode>
              </torsional>
            </friction>
            <bounce>
              <restitution_coefficient>0</restitution_coefficient>
              <threshold>1e+06</threshold>
            </bounce>
            <contact>
              <collide_without_contact>0</collide_without_contact>
              <collide_without_contact_bitmask>1</collide_without_contact_bitmask>
              <collide_bitmask>1</collide_bitmask>
              <ode>
                <soft_cfm>0</soft_cfm>
                <soft_erp>0.2</soft_erp>
                <kp>1e+13</kp>
                <kd>1</kd>
                <max_vel>0.01</max_vel>
                <min_depth>0</min_depth>
              </ode>
              <bullet>
                <split_impulse>1</split_impulse>
                <split_impulse_penetration_threshold>-0.01</split_impulse_penetration_threshold>
                <soft_cfm>0</soft_cfm>
                <soft_erp>0.2</soft_erp>
                <kp>1e+13</kp>
                <kd>1</kd>
              </bullet>
            </contact>
          </surface>
        </collision>
        <enable_wind>0</enable_wind>
      </link>
      <static>1</static>
      <allow_auto_disable>1</allow_auto_disable>
      <pose>0.691687 0.083932 0 0 -0 0</pose>
    </model>
    <model name='salt'>
      <link name='base_link'>
        <pose>0 0 0 0 -0 0</pose>
        <inertial>
          <pose>0 0 0 0 -0 0</pose>
          <mass>5</mass>
          <inertia>
            <ixx>1</ixx>
            <ixy>0</ixy>
            <ixz>0</ixz>
            <iyy>1</iyy>
            <iyz>0</iyz>
            <izz>1</izz>
          </inertia>
        </inertial>
        <self_collide>0</self_collide>
        <kinematic>0</kinematic>
        <visual name='base_link_visual'>
          <pose>0 0 0 0 -0 0</pose>
          <geometry>
            <mesh>
              <scale>1 1 1</scale>
              <uri>model://salt/meshes/model.dae</uri>
            </mesh>
          </geometry>
          <cast_shadows>1</cast_shadows>
          <transparency>0</transparency>
        </visual>
        <collision name='base_link_collision'>
          <laser_retro>0</laser_retro>
          <max_contacts>10</max_contacts>
          <pose>0 0 0.072 0 -0 0</pose>
          <geometry>
            <box>
              <size>0.061 0.046 0.144</size>
            </box>
          </geometry>
          <surface>
            <friction>
              <ode>
                <mu>1</mu>
                <mu2>1</mu2>
                <fdir1>0 0 0</fdir1>
                <slip1>0</slip1>
                <slip2>0</slip2>
              </ode>
              <torsional>
                <coefficient>1</coefficient>
                <patch_radius>0</patch_radius>
                <surface_radius>0</surface_radius>
                <use_patch_radius>1</use_patch_radius>
                <ode>
                  <slip>0</slip>
                </ode>
              </torsional>
            </friction>
            <bounce>
              <restitution_coefficient>0</restitution_coefficient>
              <threshold>1e+06</threshold>
            </bounce>
            <contact>
              <collide_without_contact>0</collide_without_contact>
              <collide_without_contact_bitmask>1</collide_without_contact_bitmask>
              <collide_bitmask>1</collide_bitmask>
              <ode>
                <soft_cfm>0</soft_cfm>
                <soft_erp>0.2</soft_erp>
                <kp>1e+13</kp>
                <kd>1</kd>
                <max_vel>0.01</max_vel>
                <min_depth>0</min_depth>
              </ode>
              <bullet>
                <split_impulse>1</split_impulse>
                <split_impulse_penetration_threshold>-0.01</split_impulse_penetration_threshold>
                <soft_cfm>0</soft_cfm>
                <soft_erp>0.2</soft_erp>
                <kp>1e+13</kp>
                <kd>1</kd>
              </bullet>
            </contact>
          </surface>
        </collision>
        <enable_wind>0</enable_wind>
      </link>
      <static>1</static>
      <allow_auto_disable>1</allow_auto_disable>
      <pose>0.639024 -0.167973 0 0 -0 0</pose>
    </model>
    <state world_name='default'>
      <sim_time>1304 525000000</sim_time>
      <real_time>520 530932161</real_time>
      <wall_time>1684512927 40611429</wall_time>
      <iterations>286788</iterations>
      <model name='Chair'>
        <pose>2.80259 -2.97588 0.000909 0 1e-06 -5e-05</pose>
        <scale>1 1 1</scale>
        <link name='body'>
          <pose>2.80259 -2.97588 0.000909 1e-06 -0 1.57075</pose>
          <velocity>0 0 0 0 -0 0</velocity>
          <acceleration>9e-06 0 16.7822 0.243399 0.733238 3e-06</acceleration>
          <wrench>9e-06 0 16.7822 0 -0 0</wrench>
        </link>
      </model>
      <model name='Suitcase1'>
        <pose>3.82364 -1.7216 0.136359 0 -0 0</pose>
        <scale>1 1 1</scale>
        <link name='body'>
          <pose>3.82364 -1.7216 0.136359 0 -0 0</pose>
          <velocity>0 0 0 0 -0 0</velocity>
          <acceleration>0 0 0 0 -0 0</acceleration>
          <wrench>0 0 0 0 -0 0</wrench>
        </link>
      </model>
      <model name='cafe'>
        <pose>3.57696 -1.34797 -0.188891 0 -0 0</pose>
        <scale>1 1 1</scale>
        <link name='link'>
          <pose>3.57696 -1.34797 -0.188891 0 -0 0</pose>
          <velocity>0 0 0 0 -0 0</velocity>
          <acceleration>0 0 0 0 -0 0</acceleration>
          <wrench>0 0 0 0 -0 0</wrench>
        </link>
      </model>
      <model name='ground_plane'>
        <pose>0 0 0 0 -0 0</pose>
        <scale>1 1 1</scale>
        <link name='link'>
          <pose>0 0 0 0 -0 0</pose>
          <velocity>0 0 0 0 -0 0</velocity>
          <acceleration>0 0 0 0 -0 0</acceleration>
          <wrench>0 0 0 0 -0 0</wrench>
        </link>
      </model>
      <model name='locobot'>
        <pose>1 0 0 0 -0 0</pose>
        <scale>1 1 1</scale>
        <link name='locobot/ar_tag_link'>
          <pose>1.49379 0.001262 0.485354 0.002544 0.066388 0.003294</pose>
          <velocity>0 0 0 0 -0 0</velocity>
          <acceleration>0.63833 0.117079 0.099146 1.83316 -0.4905 -2.98996</acceleration>
          <wrench>0.010537 0.001933 0.001637 0 -0 0</wrench>
        </link>
        <link name='locobot/arm_base_link'>
          <pose>1.09728 1e-06 0.107948 -5.8e-05 1.2e-05 4e-06</pose>
          <velocity>0 0 0 0 -0 0</velocity>
          <acceleration>0.18663 -0.010441 0.424878 2.71858 -0.062332 -1.8909</acceleration>
          <wrench>0.070859 -0.003964 0.161315 0 -0 0</wrench>
        </link>
        <link name='locobot/base_footprint'>
          <pose>1 0 0 0 -0 0</pose>
          <velocity>0 0 0 0 -0 0</velocity>
          <acceleration>0.224067 0.145592 0.55361 -0.841 -1.16972 1.73366</acceleration>
          <wrench>0.542534 0.352522 1.34046 0 -0 0</wrench>
        </link>
        <link name='locobot/battery_link'>
          <pose>0.993 -0 0.110949 1e-06 -2.5e-05 -4e-06</pose>
          <velocity>0 0 0 0 -0 0</velocity>
          <acceleration>0.044163 0.216267 0.436428 -0.377671 -0.954422 -3.00526</acceleration>
          <wrench>0.052731 0.258222 0.521095 0 -0 0</wrench>
        </link>
        <link name='locobot/camera_link'>
          <pose>1.0924 -0.040529 0.561575 -1e-06 0.002173 -0.749661</pose>
          <velocity>0 0 0 0 -0 0</velocity>
          <acceleration>-1.0471 1.04114 -0.356186 -3.12282 0.231158 -0.284144</acceleration>
          <wrench>-0.075391 0.074962 -0.025645 0 -0 0</wrench>
        </link>
        <link name='locobot/camera_tower_link'>
          <pose>0.976003 -4.4e-05 0.098431 0 -3e-06 0</pose>
          <velocity>0 0 0 0 -0 0</velocity>
          <acceleration>-0.189574 0.257027 0.503355 -0.553675 -1.37923 0.404931</acceleration>
          <wrench>-0.448573 0.608182 1.19105 0 -0 0</wrench>
        </link>
        <link name='locobot/ee_arm_link'>
          <pose>1.508 0.001415 0.442767 0.002545 0.066387 0.003294</pose>
          <velocity>0 0 0 0 -0 0</velocity>
          <acceleration>0.970762 0.07376 0.077621 3.0656 -0.46426 3.04227</acceleration>
          <wrench>0.000971 7.4e-05 7.8e-05 0 -0 0</wrench>
        </link>
        <link name='locobot/ee_gripper_link'>
          <pose>1.55846 0.00158 0.439414 0.002518 0.066427 0.003284</pose>
          <velocity>0 0 0 0 -0 0</velocity>
          <acceleration>1.0112 0.063537 0.129424 -1.66452 1.43919 -2.43639</acceleration>
          <wrench>0.001011 6.4e-05 0.000129 0 -0 0</wrench>
        </link>
        <link name='locobot/fingers_link'>
          <pose>1.53095 0.00149 0.441244 0.002518 0.066427 0.003284</pose>
          <velocity>0 0 0 0 -0 0</velocity>
          <acceleration>1.06984 0.046677 0.116138 -1.67906 1.41647 -2.39337</acceleration>
          <wrench>0.00107 4.7e-05 0.000116 0 -0 0</wrench>
        </link>
        <link name='locobot/gripper_bar_link'>
          <pose>1.508 0.001414 0.442773 0.002528 0.066447 0.003286</pose>
          <velocity>0 0 0 0 -0 0</velocity>
          <acceleration>0.829497 0.039752 0.208574 -0.140753 0.88294 2.49398</acceleration>
          <wrench>0.028368 0.001359 0.007133 0 -0 0</wrench>
        </link>
        <link name='locobot/gripper_link'>
          <pose>1.46509 0.001272 0.445628 0.00254 0.066388 0.003287</pose>
          <velocity>0 0 0 0 -0 0</velocity>
          <acceleration>-1.56706 0.60013 0.316547 -0.592141 0.955871 0.527606</acceleration>
          <wrench>-0.114215 0.043741 0.023072 0 -0 0</wrench>
        </link>
        <link name='locobot/gripper_prop_link'>
          <pose>1.51348 0.001432 0.442407 0.011293 0.066387 0.003294</pose>
          <velocity>0 0 0 0 -0 0</velocity>
          <acceleration>-0.786565 0.472397 0.124964 -2.53274 -0.560794 -1.25667</acceleration>
          <wrench>-0.003414 0.00205 0.000542 0 -0 0</wrench>
        </link>
        <link name='locobot/left_finger_link'>
          <pose>1.53084 0.034118 0.441326 0.002486 0.066427 0.003283</pose>
          <velocity>0 0 0 0 -0 0</velocity>
          <acceleration>-1.15739 0.372582 0.284675 0.574491 -0.231176 0.202564</acceleration>
          <wrench>-0.018803 0.006053 0.004625 0 -0 0</wrench>
        </link>
        <link name='locobot/lower_forearm_link'>
          <pose>1.32532 0.000802 0.453573 -0.004707 0.048465 0.003403</pose>
          <velocity>0 0 0 0 -0 0</velocity>
          <acceleration>-2.04302 0.733815 0.546832 -1.604 1.03074 -0.201604</acceleration>
          <wrench>-0.451489 0.162166 0.120845 0 -0 0</wrench>
        </link>
        <link name='locobot/pan_link'>
          <pose>1.02323 -4.3e-05 0.542681 -3e-06 3e-06 -0.749662</pose>
          <velocity>0 0 0 0 -0 0</velocity>
          <acceleration>-0.626109 0.463787 0.47587 -2.55208 0.055735 -1.11177</acceleration>
          <wrench>-0.061983 0.045914 0.04711 0 -0 0</wrench>
        </link>
        <link name='locobot/plate_link'>
          <pose>1 -0 0.098448 -1.2e-05 -3e-06 1e-06</pose>
          <velocity>0 0 0 0 -0 0</velocity>
          <acceleration>0.451393 0.159657 0.458378 -1.84121 -0.869692 -2.1744</acceleration>
          <wrench>0.258195 0.091323 0.26219 0 -0 0</wrench>
        </link>
        <link name='locobot/right_finger_link'>
          <pose>1.53106 -0.035511 0.441155 0.002518 0.066426 0.003287</pose>
          <velocity>0 0 0 0 -0 0</velocity>
          <acceleration>-1.21607 0.783824 -0.034614 -0.574212 -1.04784 -2.72988</acceleration>
          <wrench>-0.019756 0.012734 -0.000562 0 -0 0</wrench>
        </link>
        <link name='locobot/shoulder_link'>
          <pose>1.09728 3e-06 0.174123 -9e-05 2.6e-05 0.003409</pose>
          <velocity>0 0 0 0 -0 0</velocity>
          <acceleration>0.103443 -0.08509 0.408302 -1.01008 0.687333 2.06088</acceleration>
          <wrench>0.049743 -0.040918 0.196344 0 -0 0</wrench>
        </link>
        <link name='locobot/tilt_link'>
          <pose>1.04155 -0.017101 0.561681 -3e-06 0.002168 -0.749662</pose>
          <velocity>0 0 0 0 -0 0</velocity>
          <acceleration>-0.98088 0.997802 -0.270743 -1.84819 -1.3074 -0.063256</acceleration>
          <wrench>-0.090089 0.091643 -0.024866 0 -0 0</wrench>
        </link>
        <link name='locobot/upper_arm_link'>
          <pose>1.09728 6e-06 0.212773 -7.9e-05 0.014028 0.003411</pose>
          <velocity>0 0 0 0 -0 0</velocity>
          <acceleration>-0.625067 0.233557 0.417182 1.3474 -0.449027 -1.16286</acceleration>
          <wrench>-0.269286 0.100619 0.179727 0 -0 0</wrench>
        </link>
        <link name='locobot/upper_forearm_link'>
          <pose>1.15053 0.000207 0.46205 -8.4e-05 0.048458 0.003406</pose>
          <velocity>0 0 0 0 -0 0</velocity>
          <acceleration>-1.55913 0.616559 0.442324 1.34882 1.10066 -1.00277</acceleration>
          <wrench>-0.365754 0.144638 0.103764 0 -0 0</wrench>
        </link>
        <link name='locobot/wheel_left_link'>
          <pose>1.00003 0.114995 0.035412 -1.57079 -1.09595 1.3e-05</pose>
          <velocity>0 0 0 0 -0 0</velocity>
          <acceleration>-0.051739 0.029152 0.009448 -0.922137 -1.4595 1.66967</acceleration>
          <wrench>-0.000517 0.000292 9.4e-05 0 -0 0</wrench>
        </link>
        <link name='locobot/wheel_right_link'>
          <pose>0.999974 -0.115001 0.035371 -1.57083 1.1486 -2.6e-05</pose>
          <velocity>0 0 0 0 -0 0</velocity>
          <acceleration>-0.006747 0.013155 0.025667 -0.447394 -0.188149 1.20608</acceleration>
          <wrench>-6.7e-05 0.000132 0.000257 0 -0 0</wrench>
        </link>
        <link name='locobot/wrist_link'>
          <pose>1.40023 0.001057 0.44994 -0.004715 0.066383 0.003305</pose>
          <velocity>0 0 0 0 -0 0</velocity>
          <acceleration>-1.90529 0.71392 0.344268 -1.55115 0.954429 2.25709</acceleration>
          <wrench>-0.161868 0.060652 0.029248 0 -0 0</wrench>
        </link>
      </model>
      <model name='milk'>
        <pose>0.691687 0.083932 0.192731 0 -0 0</pose>
        <scale>1 1 1</scale>
        <link name='box_body'>
          <pose>0.691687 0.083932 0.192731 0 -0 0</pose>
          <velocity>0 0 0 0 -0 0</velocity>
          <acceleration>0 0 0 0 -0 0</acceleration>
          <wrench>0 0 0 0 -0 0</wrench>
        </link>
      </model>
      <model name='salt'>
        <pose>0.639024 -0.167973 0.178087 0 -0 0</pose>
        <scale>1 1 1</scale>
        <link name='base_link'>
          <pose>0.639024 -0.167973 0.178087 0 -0 0</pose>
          <velocity>0 0 0 0 -0 0</velocity>
          <acceleration>0 0 0 0 -0 0</acceleration>
          <wrench>0 0 0 0 -0 0</wrench>
        </link>
      </model>
      <light name='sun'>
        <pose>0 0 10 0 -0 0</pose>
      </light>
    </state>
    <gui fullscreen='0'>
      <camera name='user_camera'>
        <pose>4.95913 -11.2698 7.13168 0 0.548214 2.02398</pose>
        <view_controller>orbit</view_controller>
        <projection_type>perspective</projection_type>
      </camera>
    </gui>
    <model name='Suitcase1'>
      <static>1</static>
      <link name='body'>
        <pose>0 0 0 0 -0 0</pose>
        <visual name='visual'>
          <geometry>
            <mesh>
              <uri>https://fuel.gazebosim.org/1.0/openrobotics/models/suitcase1/1/files/meshes/Suitcase1.obj</uri>
            </mesh>
          </geometry>
        </visual>
        <collision name='collision'>
          <geometry>
            <mesh>
              <uri>https://fuel.gazebosim.org/1.0/openrobotics/models/suitcase1/1/files/meshes/Suitcase1_Col.obj</uri>
            </mesh>
          </geometry>
          <max_contacts>10</max_contacts>
          <surface>
            <contact>
              <ode/>
            </contact>
            <bounce/>
            <friction>
              <torsional>
                <ode/>
              </torsional>
              <ode/>
            </friction>
          </surface>
        </collision>
        <self_collide>0</self_collide>
        <enable_wind>0</enable_wind>
        <kinematic>0</kinematic>
      </link>
      <pose>0.704196 -0.88809 0 0 -0 0</pose>
    </model>
    <model name='Chair'>
      <link name='body'>
        <pose>0 0 0 0 -0 1.5708</pose>
        <visual name='visual'>
          <geometry>
            <mesh>
              <uri>https://fuel.gazebosim.org/1.0/openrobotics/models/chair/2/files/meshes/Chair.obj</uri>
              <scale>0.00817 0.00817 0.00817</scale>
            </mesh>
          </geometry>
        </visual>
        <collision name='collision'>
          <geometry>
            <mesh>
              <uri>https://fuel.gazebosim.org/1.0/openrobotics/models/chair/2/files/meshes/Chair.obj</uri>
              <scale>0.00817 0.00817 0.00817</scale>
            </mesh>
          </geometry>
          <max_contacts>10</max_contacts>
          <surface>
            <contact>
              <ode/>
            </contact>
            <bounce/>
            <friction>
              <torsional>
                <ode/>
              </torsional>
              <ode/>
            </friction>
          </surface>
        </collision>
        <self_collide>0</self_collide>
        <inertial>
          <pose>0 0 0 0 -0 0</pose>
          <inertia>
            <ixx>1</ixx>
            <ixy>0</ixy>
            <ixz>0</ixz>
            <iyy>1</iyy>
            <iyz>0</iyz>
            <izz>1</izz>
          </inertia>
          <mass>1</mass>
        </inertial>
        <enable_wind>0</enable_wind>
        <kinematic>0</kinematic>
      </link>
      <pose>1.36318 1.91753 0 0 -0 0</pose>
    </model>
    <model name='locobot'>
      <link name='locobot/base_footprint'>
        <inertial>
          <pose>0.009866 2.6e-05 0.010277 0 -0 0</pose>
          <mass>2.4213</mass>
          <inertia>
            <ixx>0.0224044</ixx>
            <ixy>-2.89213e-06</ixy>
            <ixz>4.10737e-06</ixz>
            <iyy>0.0226237</iyy>
            <iyz>-1.24762e-06</iyz>
            <izz>0.0394834</izz>
          </inertia>
        </inertial>
        <collision name='locobot/base_footprint_fixed_joint_lump__locobot/base_link_collision'>
          <pose>0 0 0.06969 0 -0 0</pose>
          <geometry>
            <cylinder>
              <length>0.10938</length>
              <radius>0.178</radius>
            </cylinder>
          </geometry>
          <surface>
            <contact>
              <ode/>
            </contact>
            <friction>
              <ode>
                <mu>0.3</mu>
                <mu2>0.3</mu2>
              </ode>
              <torsional>
                <ode/>
              </torsional>
            </friction>
            <bounce/>
          </surface>
          <max_contacts>10</max_contacts>
        </collision>
        <collision name='locobot/base_footprint_fixed_joint_lump__locobot/caster_back_link_collision_1'>
          <pose>-0.135 0 0.0192 -1.5708 0 0</pose>
          <geometry>
            <cylinder>
              <length>0.0176</length>
              <radius>0.017</radius>
            </cylinder>
          </geometry>
          <surface>
            <contact>
              <ode>
                <kp>1e+06</kp>
                <kd>100</kd>
                <max_vel>1</max_vel>
                <min_depth>0.001</min_depth>
              </ode>
            </contact>
            <friction>
              <ode>
                <mu>0</mu>
                <mu2>0</mu2>
              </ode>
              <torsional>
                <ode/>
              </torsional>
            </friction>
            <bounce/>
          </surface>
          <max_contacts>10</max_contacts>
        </collision>
        <collision name='locobot/base_footprint_fixed_joint_lump__locobot/caster_front_link_collision_2'>
          <pose>0.115 0 0.0172 -1.5708 0 0</pose>
          <geometry>
            <cylinder>
              <length>0.0176</length>
              <radius>0.017</radius>
            </cylinder>
          </geometry>
          <surface>
            <contact>
              <ode>
                <kp>1e+06</kp>
                <kd>100</kd>
                <max_vel>1</max_vel>
                <min_depth>0.001</min_depth>
              </ode>
            </contact>
            <friction>
              <ode>
                <mu>0</mu>
                <mu2>0</mu2>
              </ode>
              <torsional>
                <ode/>
              </torsional>
            </friction>
            <bounce/>
          </surface>
          <max_contacts>10</max_contacts>
        </collision>
        <visual name='locobot/base_footprint_fixed_joint_lump__locobot/base_link_visual'>
          <pose>0.001 0 0.06219 0 -0 0</pose>
          <geometry>
            <mesh>
              <scale>1 1 1</scale>
              <uri>/home/david/catkin_ws/src/locobot_simulation_david/meshes/locobot_meshes/locobot_main_body.dae</uri>
            </mesh>
          </geometry>
        </visual>
        <sensor name='bumpers' type='contact'>
          <always_on>1</always_on>
          <update_rate>50</update_rate>
          <visualize>1</visualize>
          <contact>
            <collision>base_footprint</collision>
            <topic>__default_topic__</topic>
          </contact>
          <pose>0 0 0.0102 0 -0 0</pose>
        </sensor>
        <sensor name='cliff_sensor_front' type='ray'>
          <always_on>1</always_on>
          <update_rate>50</update_rate>
          <visualize>1</visualize>
          <ray>
            <scan>
              <horizontal>
                <samples>50</samples>
                <resolution>1</resolution>
                <min_angle>-0.0436</min_angle>
                <max_angle>0.0436</max_angle>
              </horizontal>
              <vertical>
                <samples>1</samples>
                <min_angle>0</min_angle>
                <max_angle>0</max_angle>
              </vertical>
            </scan>
            <range>
              <min>0.01</min>
              <max>0.15</max>
              <resolution>1</resolution>
            </range>
          </ray>
          <pose>0.156 0 0.0316 3.14159 1.57079 3.14159</pose>
        </sensor>
        <sensor name='cliff_sensor_left' type='ray'>
          <always_on>1</always_on>
          <update_rate>50</update_rate>
          <visualize>1</visualize>
          <ray>
            <scan>
              <horizontal>
                <samples>50</samples>
                <resolution>1</resolution>
                <min_angle>-0.0436</min_angle>
                <max_angle>0.0436</max_angle>
              </horizontal>
              <vertical>
                <samples>1</samples>
                <min_angle>0</min_angle>
                <max_angle>0</max_angle>
              </vertical>
            </scan>
            <range>
              <min>0.01</min>
              <max>0.15</max>
              <resolution>1</resolution>
            </range>
          </ray>
          <pose>0.08734 0.13601 0.0316 3.14159 1.57079 3.14159</pose>
        </sensor>
        <sensor name='cliff_sensor_right' type='ray'>
          <always_on>1</always_on>
          <update_rate>50</update_rate>
          <visualize>1</visualize>
          <ray>
            <scan>
              <horizontal>
                <samples>50</samples>
                <resolution>1</resolution>
                <min_angle>-0.0436</min_angle>
                <max_angle>0.0436</max_angle>
              </horizontal>
              <vertical>
                <samples>1</samples>
                <min_angle>0</min_angle>
                <max_angle>0</max_angle>
              </vertical>
            </scan>
            <range>
              <min>0.01</min>
              <max>0.15</max>
              <resolution>1</resolution>
            </range>
          </ray>
          <pose>0.085 -0.13601 0.0316 3.14159 1.57079 3.14159</pose>
        </sensor>
        <sensor name='imu' type='imu'>
          <always_on>1</always_on>
          <update_rate>50</update_rate>
          <visualize>0</visualize>
          <imu>
            <noise>
              <type>gaussian</type>
              <rate>
                <mean>0.0</mean>
                <stddev>0.00000196</stddev>
                <bias_mean>0.0</bias_mean>
                <bias_stddev>0.0</bias_stddev>
              </rate>
              <accel>
                <mean>0.0</mean>
                <stddev>1.7e-2</stddev>
                <bias_mean>0.1</bias_mean>
                <bias_stddev>0.001</bias_stddev>
              </accel>
            </noise>
          </imu>
          <pose>0.056 0.062 0.0304 0 -0 0</pose>
        </sensor>
        <self_collide>0</self_collide>
        <enable_wind>0</enable_wind>
        <kinematic>0</kinematic>
      </link>
      <joint name='camera_tower' type='revolute'>
        <pose relative_to='locobot/base_footprint'>-0.023997 -4.4e-05 0.09843 0 -0 0</pose>
        <parent>locobot/base_footprint</parent>
        <child>locobot/camera_tower_link</child>
        <axis>
          <limit>
            <lower>0</lower>
            <upper>0</upper>
          </limit>
          <dynamics>
            <damping>0</damping>
            <friction>0</friction>
            <spring_reference>0</spring_reference>
            <spring_stiffness>0</spring_stiffness>
          </dynamics>
          <xyz>0 0 1</xyz>
        </axis>
        <physics>
          <ode>
            <limit>
              <cfm>0</cfm>
              <erp>0.2</erp>
            </limit>
          </ode>
        </physics>
      </joint>
      <link name='locobot/camera_tower_link'>
        <pose relative_to='camera_tower'>0 0 0 0 -0 0</pose>
        <inertial>
          <pose>-0.037221 -0.002611 0.17446 0 -0 0</pose>
          <mass>2.36622</mass>
          <inertia>
            <ixx>0.06285</ixx>
            <ixy>0.0002152</ixy>
            <ixz>0.006563</ixz>
            <iyy>0.0546</iyy>
            <iyz>-0.0004738</iyz>
            <izz>0.01793</izz>
          </inertia>
        </inertial>
        <collision name='locobot/camera_tower_link_collision'>
          <pose>0 0 0 0 -0 0</pose>
          <geometry>
            <mesh>
              <scale>0.001 0.001 0.001</scale>
              <uri>/home/david/catkin_ws/src/locobot_simulation_david/meshes/locobot_meshes/locobot_camera_tower_large_simple.stl</uri>
            </mesh>
          </geometry>
          <surface>
            <contact>
              <ode/>
            </contact>
            <friction>
              <ode/>
              <torsional>
                <ode/>
              </torsional>
            </friction>
            <bounce/>
          </surface>
          <max_contacts>10</max_contacts>
        </collision>
        <visual name='locobot/camera_tower_link_visual'>
          <pose>0 0 0 0 -0 0</pose>
          <geometry>
            <mesh>
              <scale>0.001 0.001 0.001</scale>
              <uri>/home/david/catkin_ws/src/locobot_simulation_david/meshes/locobot_meshes/locobot_camera_tower_large.stl</uri>
            </mesh>
          </geometry>
          <material>
            <script>
              <name>Custom/Interbotix</name>
              <uri>file://media/materials/scripts/gazebo.material</uri>
            </script>
          </material>
        </visual>
        <self_collide>0</self_collide>
        <enable_wind>0</enable_wind>
        <kinematic>0</kinematic>
      </link>
      <joint name='pan' type='revolute'>
        <pose relative_to='locobot/camera_tower_link'>0.047228 0 0.44425 0 -0 0</pose>
        <parent>locobot/camera_tower_link</parent>
        <child>locobot/pan_link</child>
        <axis>
          <xyz>0 0 1</xyz>
          <limit>
            <lower>-1.5708</lower>
            <upper>1.5708</upper>
            <effort>2</effort>
            <velocity>3.14159</velocity>
          </limit>
          <dynamics>
            <spring_reference>0</spring_reference>
            <spring_stiffness>0</spring_stiffness>
          </dynamics>
        </axis>
      </joint>
      <link name='locobot/pan_link'>
        <pose relative_to='pan'>0 0 0 0 -0 0</pose>
        <inertial>
          <pose>0.012 0.000496 0.018504 0 -0 1.5708</pose>
          <mass>0.098997</mass>
          <inertia>
            <ixx>2.763e-05</ixx>
            <ixy>4.18e-08</ixy>
            <ixz>5.145e-07</ixz>
            <iyy>2.043e-05</iyy>
            <iyz>-4.21e-08</iyz>
            <izz>2.763e-05</izz>
          </inertia>
        </inertial>
        <collision name='locobot/pan_link_collision'>
          <pose>0 0 0 0 -0 1.5708</pose>
          <geometry>
            <mesh>
              <scale>0.001 0.001 0.001</scale>
              <uri>/home/david/catkin_ws/src/locobot_simulation_david/meshes/locobot_meshes/locobot_pan.stl</uri>
            </mesh>
          </geometry>
          <surface>
            <contact>
              <ode/>
            </contact>
            <friction>
              <ode/>
              <torsional>
                <ode/>
              </torsional>
            </friction>
            <bounce/>
          </surface>
          <max_contacts>10</max_contacts>
        </collision>
        <visual name='locobot/pan_link_visual'>
          <pose>0 0 0 0 -0 1.5708</pose>
          <geometry>
            <mesh>
              <scale>0.001 0.001 0.001</scale>
              <uri>/home/david/catkin_ws/src/locobot_simulation_david/meshes/locobot_meshes/locobot_pan.stl</uri>
            </mesh>
          </geometry>
          <material>
            <script>
              <name>Custom/Interbotix</name>
              <uri>file://media/materials/scripts/gazebo.material</uri>
            </script>
          </material>
        </visual>
        <self_collide>1</self_collide>
        <enable_wind>0</enable_wind>
        <kinematic>0</kinematic>
      </link>
      <joint name='tilt' type='revolute'>
        <pose relative_to='locobot/pan_link'>0.025034 0 0.019 0 -0 0</pose>
        <parent>locobot/pan_link</parent>
        <child>locobot/tilt_link</child>
        <axis>
          <xyz>0 1 0</xyz>
          <limit>
            <lower>-1.5708</lower>
            <upper>1.309</upper>
            <effort>2</effort>
            <velocity>3.14159</velocity>
          </limit>
          <dynamics>
            <spring_reference>0</spring_reference>
            <spring_stiffness>0</spring_stiffness>
          </dynamics>
        </axis>
      </joint>
      <link name='locobot/tilt_link'>
        <pose relative_to='tilt'>0 0 0 0 -0 0</pose>
        <inertial>
          <pose>0.039793 0.001318 1.1e-05 0 -0 1.5708</pose>
          <mass>0.091845</mass>
          <inertia>
            <ixx>1.55765e-05</ixx>
            <ixy>2.32424e-07</ixy>
            <ixz>2.47885e-08</ixz>
            <iyy>5.29475e-05</iyy>
            <iyz>-2.28468e-08</iyz>
            <izz>6.00158e-05</izz>
          </inertia>
        </inertial>
        <collision name='locobot/tilt_link_collision'>
          <pose>0 0 0 0 -0 1.5708</pose>
          <geometry>
            <mesh>
              <scale>0.001 0.001 0.001</scale>
              <uri>/home/david/catkin_ws/src/locobot_simulation_david/meshes/locobot_meshes/locobot_tilt.stl</uri>
            </mesh>
          </geometry>
          <surface>
            <contact>
              <ode/>
            </contact>
            <friction>
              <ode/>
              <torsional>
                <ode/>
              </torsional>
            </friction>
            <bounce/>
          </surface>
          <max_contacts>10</max_contacts>
        </collision>
        <collision name='locobot/tilt_link_fixed_joint_lump__locobot/ros_logical_camera_collision_1'>
          <pose>0.05318 0.0175 9e-06 0 -0 0</pose>
          <geometry>
            <mesh>
              <scale>0.001 0.001 0.001</scale>
              <uri>/home/david/catkin_ws/src/locobot_simulation_david/meshes/locobot_meshes/locobot_camera.stl</uri>
            </mesh>
          </geometry>
          <surface>
            <contact>
              <ode/>
            </contact>
            <friction>
              <ode/>
              <torsional>
                <ode/>
              </torsional>
            </friction>
            <bounce/>
          </surface>
          <max_contacts>10</max_contacts>
        </collision>
        <visual name='locobot/tilt_link_visual'>
          <pose>0 0 0 0 -0 1.5708</pose>
          <geometry>
            <mesh>
              <scale>0.001 0.001 0.001</scale>
              <uri>/home/david/catkin_ws/src/locobot_simulation_david/meshes/locobot_meshes/locobot_tilt.stl</uri>
            </mesh>
          </geometry>
          <material>
            <script>
              <name>Custom/Interbotix</name>
              <uri>file://media/materials/scripts/gazebo.material</uri>
            </script>
          </material>
        </visual>
        <visual name='locobot/tilt_link_fixed_joint_lump__locobot/ros_logical_camera_visual_1'>
          <pose>0.05318 0.0175 9e-06 0 -0 0</pose>
          <geometry>
            <mesh>
              <scale>0.001 0.001 0.001</scale>
              <uri>/home/david/catkin_ws/src/locobot_simulation_david/meshes/locobot_meshes/locobot_camera.stl</uri>
            </mesh>
          </geometry>
        </visual>
        <self_collide>1</self_collide>
        <sensor name='logical_camera' type='logical_camera'>
          <plugin name='logical_camera_plugin' filename='liblogical_camera_plugin.so'>
            <robotNamespace>/locobot/</robotNamespace>
          </plugin>
          <logical_camera>
            <near>0.3</near>
            <far>3</far>
            <horizontal_fov>1.5</horizontal_fov>
            <aspect_ratio>1.766</aspect_ratio>
          </logical_camera>
          <visualize>0</visualize>
          <always_on>1</always_on>
          <update_rate>20</update_rate>
          <pose>0.05318 0.0175 9e-06 0 -0 0</pose>
        </sensor>
        <enable_wind>0</enable_wind>
        <kinematic>0</kinematic>
      </link>
      <joint name='camera' type='revolute'>
        <pose relative_to='locobot/tilt_link'>0.05318 0.0175 9e-06 0 -0 0</pose>
        <parent>locobot/tilt_link</parent>
        <child>locobot/camera_link</child>
        <axis>
          <limit>
            <lower>0</lower>
            <upper>0</upper>
          </limit>
          <dynamics>
            <damping>0</damping>
            <friction>0</friction>
            <spring_reference>0</spring_reference>
            <spring_stiffness>0</spring_stiffness>
          </dynamics>
          <xyz>0 0 1</xyz>
        </axis>
        <physics>
          <ode>
            <limit>
              <cfm>0</cfm>
              <erp>0.2</erp>
            </limit>
          </ode>
        </physics>
      </joint>
      <link name='locobot/camera_link'>
        <pose relative_to='camera'>0 0 0 0 -0 0</pose>
        <inertial>
          <pose>-0.008972 -0.015818 3e-06 0 -0 0</pose>
          <mass>0.072</mass>
          <inertia>
            <ixx>4.654e-05</ixx>
            <ixy>3.028e-07</ixy>
            <ixz>2.45e-08</ixz>
            <iyy>6.9128e-06</iyy>
            <iyz>2.48e-08</iyz>
            <izz>4.686e-05</izz>
          </inertia>
        </inertial>
        <collision name='locobot/camera_link_collision'>
          <pose>0 0 0 0 -0 0</pose>
          <geometry>
            <mesh>
              <scale>0.001 0.001 0.001</scale>
              <uri>/home/david/catkin_ws/src/locobot_simulation_david/meshes/locobot_meshes/locobot_camera.stl</uri>
            </mesh>
          </geometry>
          <surface>
            <contact>
              <ode/>
            </contact>
            <friction>
              <ode/>
              <torsional>
                <ode/>
              </torsional>
            </friction>
            <bounce/>
          </surface>
          <max_contacts>10</max_contacts>
        </collision>
        <visual name='locobot/camera_link_visual'>
          <pose>0 0 0 0 -0 0</pose>
          <geometry>
            <mesh>
              <scale>0.001 0.001 0.001</scale>
              <uri>/home/david/catkin_ws/src/locobot_simulation_david/meshes/locobot_meshes/locobot_camera.stl</uri>
            </mesh>
          </geometry>
          <material>
            <script>
              <name>Gazebo/Grey</name>
              <uri>file://media/materials/scripts/gazebo.material</uri>
            </script>
          </material>
        </visual>
        <self_collide>1</self_collide>
        <sensor name='camera_frame_sensor' type='depth'>
          <always_on>1</always_on>
          <update_rate>30</update_rate>
          <camera>
            <horizontal_fov>0.994837</horizontal_fov>
            <image>
              <format>R8G8B8</format>
              <width>640</width>
              <height>480</height>
            </image>
            <clip>
              <near>0.01</near>
              <far>10</far>
            </clip>
          </camera>
          <plugin name='camera_frame_controller' filename='libgazebo_ros_openni_kinect.so'>
            <alwaysOn>1</alwaysOn>
            <updateRate>0.0</updateRate>
            <cameraName>camera</cameraName>
            <imageTopicName>color/image_raw</imageTopicName>
            <cameraInfoTopicName>color/camera_info</cameraInfoTopicName>
            <depthImageTopicName>aligned_depth_to_color/image_raw</depthImageTopicName>
            <depthImageCameraInfoTopicName>aligned_depth_to_color/camera_info</depthImageCameraInfoTopicName>
            <pointCloudTopicName>depth_registered/points</pointCloudTopicName>
            <frameName>camera_color_optical_frame</frameName>
            <pointCloudCutoff>10</pointCloudCutoff>
            <distortionK1>0.00000001</distortionK1>
            <distortionK2>0.00000001</distortionK2>
            <distortionK3>0.00000001</distortionK3>
            <distortionT1>0.00000001</distortionT1>
            <distortionT2>0.00000001</distortionT2>
            <CxPrime>0</CxPrime>
            <Cx>0</Cx>
            <Cy>0</Cy>
            <focalLength>0</focalLength>
            <hackBaseline>0</hackBaseline>
            <robotNamespace>/locobot/</robotNamespace>
          </plugin>
        </sensor>
        <enable_wind>0</enable_wind>
        <kinematic>0</kinematic>
      </link>
      <joint name='plate' type='revolute'>
        <pose relative_to='locobot/base_footprint'>0 0 0.09845 0 -0 0</pose>
        <parent>locobot/base_footprint</parent>
        <child>locobot/plate_link</child>
        <axis>
          <limit>
            <lower>0</lower>
            <upper>0</upper>
          </limit>
          <dynamics>
            <damping>0</damping>
            <friction>0</friction>
            <spring_reference>0</spring_reference>
            <spring_stiffness>0</spring_stiffness>
          </dynamics>
          <xyz>0 0 1</xyz>
        </axis>
        <physics>
          <ode>
            <limit>
              <cfm>0</cfm>
              <erp>0.2</erp>
            </limit>
          </ode>
        </physics>
      </joint>
      <link name='locobot/plate_link'>
        <pose relative_to='plate'>0 0 0 0 -0 0</pose>
        <inertial>
          <pose>0.050816 0 0.00475 0 -0 0</pose>
          <mass>0.571995</mass>
          <inertia>
            <ixx>0.003115</ixx>
            <ixy>0</ixy>
            <ixz>0</ixz>
            <iyy>0.001813</iyy>
            <iyz>0</iyz>
            <izz>0.004919</izz>
          </inertia>
        </inertial>
        <collision name='locobot/plate_link_collision'>
          <pose>0 0 0 0 -0 0</pose>
          <geometry>
            <mesh>
              <scale>0.001 0.001 0.001</scale>
              <uri>/home/david/catkin_ws/src/locobot_simulation_david/meshes/locobot_meshes/locobot_base_plate.stl</uri>
            </mesh>
          </geometry>
          <surface>
            <contact>
              <ode/>
            </contact>
            <friction>
              <ode/>
              <torsional>
                <ode/>
              </torsional>
            </friction>
            <bounce/>
          </surface>
          <max_contacts>10</max_contacts>
        </collision>
        <visual name='locobot/plate_link_visual'>
          <pose>0 0 0 0 -0 0</pose>
          <geometry>
            <mesh>
              <scale>0.001 0.001 0.001</scale>
              <uri>/home/david/catkin_ws/src/locobot_simulation_david/meshes/locobot_meshes/locobot_base_plate.stl</uri>
            </mesh>
          </geometry>
          <material>
            <script>
              <name>Custom/Interbotix</name>
              <uri>file://media/materials/scripts/gazebo.material</uri>
            </script>
          </material>
        </visual>
        <self_collide>0</self_collide>
        <enable_wind>0</enable_wind>
        <kinematic>0</kinematic>
      </link>
      <joint name='arm_base_link_joint' type='revolute'>
        <pose relative_to='locobot/plate_link'>0.097277 0 0.0095 0 -0 0</pose>
        <parent>locobot/plate_link</parent>
        <child>locobot/arm_base_link</child>
        <axis>
          <limit>
            <lower>0</lower>
            <upper>0</upper>
          </limit>
          <dynamics>
            <damping>0</damping>
            <friction>0</friction>
            <spring_reference>0</spring_reference>
            <spring_stiffness>0</spring_stiffness>
          </dynamics>
          <xyz>0 0 1</xyz>
        </axis>
        <physics>
          <ode>
            <limit>
              <cfm>0</cfm>
              <erp>0.2</erp>
            </limit>
          </ode>
        </physics>
      </joint>
      <link name='locobot/arm_base_link'>
        <pose relative_to='arm_base_link_joint'>0 0 0 0 -0 0</pose>
        <inertial>
          <pose>-0.000135 -2.7e-05 0.033876 1.5708 -0 1.5708</pose>
          <mass>0.379673</mass>
          <inertia>
            <ixx>0.0004351</ixx>
            <ixy>7.07e-08</ixy>
            <ixz>2.66e-08</ixz>
            <iyy>0.0004452</iyy>
            <iyz>-2.2881e-06</iyz>
            <izz>0.0005731</izz>
          </inertia>
        </inertial>
        <collision name='locobot/arm_base_link_collision'>
          <pose>-0.095773 0 -0.10565 1.5708 -0 1.5708</pose>
          <geometry>
            <mesh>
              <scale>0.001 0.001 0.001</scale>
              <uri>/home/david/catkin_ws/src/locobot_simulation_david/meshes/mobile_wx250s_meshes/mobile_wx250s_1_base.stl</uri>
            </mesh>
          </geometry>
          <surface>
            <contact>
              <ode/>
            </contact>
            <friction>
              <ode/>
              <torsional>
                <ode/>
              </torsional>
            </friction>
            <bounce/>
          </surface>
          <max_contacts>10</max_contacts>
        </collision>
        <visual name='locobot/arm_base_link_visual'>
          <pose>-0.095773 0 -0.10565 1.5708 -0 1.5708</pose>
          <geometry>
            <mesh>
              <scale>0.001 0.001 0.001</scale>
              <uri>/home/david/catkin_ws/src/locobot_simulation_david/meshes/mobile_wx250s_meshes/mobile_wx250s_1_base.stl</uri>
            </mesh>
          </geometry>
          <material>
            <script>
              <name>Custom/Interbotix</name>
              <uri>file://media/materials/scripts/gazebo.material</uri>
            </script>
          </material>
        </visual>
        <velocity_decay>
          <linear>0.01</linear>
          <angular>0.01</angular>
        </velocity_decay>
        <self_collide>0</self_collide>
        <enable_wind>0</enable_wind>
        <kinematic>0</kinematic>
      </link>
      <joint name='waist' type='revolute'>
        <pose relative_to='locobot/arm_base_link'>0 0 0.066175 0 -0 0</pose>
        <parent>locobot/arm_base_link</parent>
        <child>locobot/shoulder_link</child>
        <axis>
          <xyz>0 0 1</xyz>
          <limit>
            <lower>-3.14158</lower>
            <upper>3.14158</upper>
            <effort>10</effort>
            <velocity>3.14159</velocity>
          </limit>
          <dynamics>
            <damping>0</damping>
            <friction>0.1</friction>
            <spring_reference>0</spring_reference>
            <spring_stiffness>0</spring_stiffness>
          </dynamics>
        </axis>
      </joint>
      <link name='locobot/shoulder_link'>
        <pose relative_to='waist'>0 0 0 0 -0 0</pose>
        <inertial>
          <pose>2.2e-05 4.1e-05 0.006629 0 -0 1.5708</pose>
          <mass>0.480879</mass>
          <inertia>
            <ixx>0.000379</ixx>
            <ixy>2.2e-09</ixy>
            <ixz>-3.561e-07</ixz>
            <iyy>0.0005557</iyy>
            <iyz>1.2245e-06</iyz>
            <izz>0.0005889</izz>
          </inertia>
        </inertial>
        <collision name='locobot/shoulder_link_collision'>
          <pose>0 0 -0.003 0 -0 1.5708</pose>
          <geometry>
            <mesh>
              <scale>0.001 0.001 0.001</scale>
              <uri>/home/david/catkin_ws/src/locobot_simulation_david/meshes/mobile_wx250s_meshes/mobile_wx250s_2_shoulder.stl</uri>
            </mesh>
          </geometry>
          <surface>
            <contact>
              <ode/>
            </contact>
            <friction>
              <ode/>
              <torsional>
                <ode/>
              </torsional>
            </friction>
            <bounce/>
          </surface>
          <max_contacts>10</max_contacts>
        </collision>
        <visual name='locobot/shoulder_link_visual'>
          <pose>0 0 -0.003 0 -0 1.5708</pose>
          <geometry>
            <mesh>
              <scale>0.001 0.001 0.001</scale>
              <uri>/home/david/catkin_ws/src/locobot_simulation_david/meshes/mobile_wx250s_meshes/mobile_wx250s_2_shoulder.stl</uri>
            </mesh>
          </geometry>
          <material>
            <script>
              <name>Custom/Interbotix</name>
              <uri>file://media/materials/scripts/gazebo.material</uri>
            </script>
          </material>
        </visual>
        <velocity_decay>
          <linear>0.01</linear>
          <angular>0.01</angular>
        </velocity_decay>
        <self_collide>1</self_collide>
        <enable_wind>0</enable_wind>
        <kinematic>0</kinematic>
      </link>
      <joint name='shoulder' type='revolute'>
        <pose relative_to='locobot/shoulder_link'>0 0 0.03865 0 -0 0</pose>
        <parent>locobot/shoulder_link</parent>
        <child>locobot/upper_arm_link</child>
        <axis>
          <xyz>0 1 0</xyz>
          <limit>
            <lower>-1.88496</lower>
            <upper>1.98968</upper>
            <effort>20</effort>
            <velocity>3.14159</velocity>
          </limit>
          <dynamics>
            <damping>0</damping>
            <friction>0.1</friction>
            <spring_reference>0</spring_reference>
            <spring_stiffness>0</spring_stiffness>
          </dynamics>
        </axis>
      </joint>
      <link name='locobot/upper_arm_link'>
        <pose relative_to='shoulder'>0 0 0 0 -0 0</pose>
        <inertial>
          <pose>0.017161 0 0.191323 0 -0 1.5708</pose>
          <mass>0.430811</mass>
          <inertia>
            <ixx>0.003463</ixx>
            <ixy>-1e-10</ixy>
            <ixz>-2e-10</ixz>
            <iyy>0.003587</iyy>
            <iyz>0.0004272</iyz>
            <izz>0.0004566</izz>
          </inertia>
        </inertial>
        <collision name='locobot/upper_arm_link_collision'>
          <pose>0 0 0 0 -0 1.5708</pose>
          <geometry>
            <mesh>
              <scale>0.001 0.001 0.001</scale>
              <uri>/home/david/catkin_ws/src/locobot_simulation_david/meshes/mobile_wx250s_meshes/mobile_wx250s_3_upper_arm.stl</uri>
            </mesh>
          </geometry>
          <surface>
            <contact>
              <ode/>
            </contact>
            <friction>
              <ode/>
              <torsional>
                <ode/>
              </torsional>
            </friction>
            <bounce/>
          </surface>
          <max_contacts>10</max_contacts>
        </collision>
        <visual name='locobot/upper_arm_link_visual'>
          <pose>0 0 0 0 -0 1.5708</pose>
          <geometry>
            <mesh>
              <scale>0.001 0.001 0.001</scale>
              <uri>/home/david/catkin_ws/src/locobot_simulation_david/meshes/mobile_wx250s_meshes/mobile_wx250s_3_upper_arm.stl</uri>
            </mesh>
          </geometry>
          <material>
            <script>
              <name>Custom/Interbotix</name>
              <uri>file://media/materials/scripts/gazebo.material</uri>
            </script>
          </material>
        </visual>
        <velocity_decay>
          <linear>0.01</linear>
          <angular>0.01</angular>
        </velocity_decay>
        <self_collide>1</self_collide>
        <enable_wind>0</enable_wind>
        <kinematic>0</kinematic>
      </link>
      <joint name='elbow' type='revolute'>
        <pose relative_to='locobot/upper_arm_link'>0.04975 0 0.25 0 -0 0</pose>
        <parent>locobot/upper_arm_link</parent>
        <child>locobot/upper_forearm_link</child>
        <axis>
          <xyz>0 1 0</xyz>
          <limit>
            <lower>-2.14675</lower>
            <upper>1.6057</upper>
            <effort>15</effort>
            <velocity>3.14159</velocity>
          </limit>
          <dynamics>
            <damping>0</damping>
            <friction>0.1</friction>
            <spring_reference>0</spring_reference>
            <spring_stiffness>0</spring_stiffness>
          </dynamics>
        </axis>
      </joint>
      <link name='locobot/upper_forearm_link'>
        <pose relative_to='elbow'>0 0 0 0 -0 0</pose>
        <inertial>
          <pose>0.107963 0.000116 0 0 -0 0</pose>
          <mass>0.234589</mass>
          <inertia>
            <ixx>3.971e-05</ixx>
            <ixy>2.3528e-06</ixy>
            <ixz>0</ixz>
            <iyy>0.0008878</iyy>
            <iyz>0</iyz>
            <izz>0.000888</izz>
          </inertia>
        </inertial>
        <collision name='locobot/upper_forearm_link_collision'>
          <pose>0 0 0 0 -0 0</pose>
          <geometry>
            <mesh>
              <scale>0.001 0.001 0.001</scale>
              <uri>/home/david/catkin_ws/src/locobot_simulation_david/meshes/mobile_wx250s_meshes/mobile_wx250s_4_upper_forearm.stl</uri>
            </mesh>
          </geometry>
          <surface>
            <contact>
              <ode/>
            </contact>
            <friction>
              <ode/>
              <torsional>
                <ode/>
              </torsional>
            </friction>
            <bounce/>
          </surface>
          <max_contacts>10</max_contacts>
        </collision>
        <visual name='locobot/upper_forearm_link_visual'>
          <pose>0 0 0 0 -0 0</pose>
          <geometry>
            <mesh>
              <scale>0.001 0.001 0.001</scale>
              <uri>/home/david/catkin_ws/src/locobot_simulation_david/meshes/mobile_wx250s_meshes/mobile_wx250s_4_upper_forearm.stl</uri>
            </mesh>
          </geometry>
          <material>
            <script>
              <name>Custom/Interbotix</name>
              <uri>file://media/materials/scripts/gazebo.material</uri>
            </script>
          </material>
        </visual>
        <velocity_decay>
          <linear>0.01</linear>
          <angular>0.01</angular>
        </velocity_decay>
        <self_collide>1</self_collide>
        <enable_wind>0</enable_wind>
        <kinematic>0</kinematic>
      </link>
      <joint name='forearm_roll' type='revolute'>
        <pose relative_to='locobot/upper_forearm_link'>0.175 0 0 0 -0 0</pose>
        <parent>locobot/upper_forearm_link</parent>
        <child>locobot/lower_forearm_link</child>
        <axis>
          <xyz>1 0 0</xyz>
          <limit>
            <lower>-3.14158</lower>
            <upper>3.14158</upper>
            <effort>2</effort>
            <velocity>3.14159</velocity>
          </limit>
          <dynamics>
            <damping>0</damping>
            <friction>0.1</friction>
            <spring_reference>0</spring_reference>
            <spring_stiffness>0</spring_stiffness>
          </dynamics>
        </axis>
      </joint>
      <link name='locobot/lower_forearm_link'>
        <pose relative_to='forearm_roll'>0 0 0 0 -0 0</pose>
        <inertial>
          <pose>0.03744 0.005223 0 3.14159 -0 0</pose>
          <mass>0.220991</mass>
          <inertia>
            <ixx>6.369e-05</ixx>
            <ixy>-2.292e-05</ixy>
            <ixz>0</ixz>
            <iyy>0.0001677</iyy>
            <iyz>0</iyz>
            <izz>0.0001834</izz>
          </inertia>
        </inertial>
        <collision name='locobot/lower_forearm_link_collision'>
          <pose>0 0 0 3.14159 -0 0</pose>
          <geometry>
            <mesh>
              <scale>0.001 0.001 0.001</scale>
              <uri>/home/david/catkin_ws/src/locobot_simulation_david/meshes/mobile_wx250s_meshes/mobile_wx250s_5_lower_forearm.stl</uri>
            </mesh>
          </geometry>
          <surface>
            <contact>
              <ode/>
            </contact>
            <friction>
              <ode/>
              <torsional>
                <ode/>
              </torsional>
            </friction>
            <bounce/>
          </surface>
          <max_contacts>10</max_contacts>
        </collision>
        <visual name='locobot/lower_forearm_link_visual'>
          <pose>0 0 0 3.14159 -0 0</pose>
          <geometry>
            <mesh>
              <scale>0.001 0.001 0.001</scale>
              <uri>/home/david/catkin_ws/src/locobot_simulation_david/meshes/mobile_wx250s_meshes/mobile_wx250s_5_lower_forearm.stl</uri>
            </mesh>
          </geometry>
          <material>
            <script>
              <name>Custom/Interbotix</name>
              <uri>file://media/materials/scripts/gazebo.material</uri>
            </script>
          </material>
        </visual>
        <velocity_decay>
          <linear>0.01</linear>
          <angular>0.01</angular>
        </velocity_decay>
        <self_collide>1</self_collide>
        <enable_wind>0</enable_wind>
        <kinematic>0</kinematic>
      </link>
      <joint name='wrist_angle' type='revolute'>
        <pose relative_to='locobot/lower_forearm_link'>0.075 0 0 0 -0 0</pose>
        <parent>locobot/lower_forearm_link</parent>
        <child>locobot/wrist_link</child>
        <axis>
          <xyz>0 1 0</xyz>
          <limit>
            <lower>-1.74533</lower>
            <upper>2.14675</upper>
            <effort>5</effort>
            <velocity>3.14159</velocity>
          </limit>
          <dynamics>
            <damping>0</damping>
            <friction>0.1</friction>
            <spring_reference>0</spring_reference>
            <spring_stiffness>0</spring_stiffness>
          </dynamics>
        </axis>
      </joint>
      <link name='locobot/wrist_link'>
        <pose relative_to='wrist_angle'>0 0 0 0 -0 0</pose>
        <inertial>
          <pose>0.04236 -1.1e-05 0.010577 0 -0 1.5708</pose>
          <mass>0.084957</mass>
          <inertia>
            <ixx>3.082e-05</ixx>
            <ixy>1.91e-08</ixy>
            <ixz>2.3e-09</ixz>
            <iyy>2.822e-05</iyy>
            <iyz>2.5481e-06</iyz>
            <izz>3.152e-05</izz>
          </inertia>
        </inertial>
        <collision name='locobot/wrist_link_collision'>
          <pose>0 0 0 0 -0 1.5708</pose>
          <geometry>
            <mesh>
              <scale>0.001 0.001 0.001</scale>
              <uri>/home/david/catkin_ws/src/locobot_simulation_david/meshes/mobile_wx250s_meshes/mobile_wx250s_6_wrist.stl</uri>
            </mesh>
          </geometry>
          <surface>
            <contact>
              <ode/>
            </contact>
            <friction>
              <ode/>
              <torsional>
                <ode/>
              </torsional>
            </friction>
            <bounce/>
          </surface>
          <max_contacts>10</max_contacts>
        </collision>
        <visual name='locobot/wrist_link_visual'>
          <pose>0 0 0 0 -0 1.5708</pose>
          <geometry>
            <mesh>
              <scale>0.001 0.001 0.001</scale>
              <uri>/home/david/catkin_ws/src/locobot_simulation_david/meshes/mobile_wx250s_meshes/mobile_wx250s_6_wrist.stl</uri>
            </mesh>
          </geometry>
          <material>
            <script>
              <name>Custom/Interbotix</name>
              <uri>file://media/materials/scripts/gazebo.material</uri>
            </script>
          </material>
        </visual>
        <velocity_decay>
          <linear>0.01</linear>
          <angular>0.01</angular>
        </velocity_decay>
        <self_collide>1</self_collide>
        <enable_wind>0</enable_wind>
        <kinematic>0</kinematic>
      </link>
      <joint name='wrist_rotate' type='revolute'>
        <pose relative_to='locobot/wrist_link'>0.065 0 0 0 -0 0</pose>
        <parent>locobot/wrist_link</parent>
        <child>locobot/gripper_link</child>
        <axis>
          <xyz>1 0 0</xyz>
          <limit>
            <lower>-3.14158</lower>
            <upper>3.14158</upper>
            <effort>1</effort>
            <velocity>3.14159</velocity>
          </limit>
          <dynamics>
            <damping>0</damping>
            <friction>0.1</friction>
            <spring_reference>0</spring_reference>
            <spring_stiffness>0</spring_stiffness>
          </dynamics>
        </axis>
      </joint>
      <link name='locobot/gripper_link'>
        <pose relative_to='wrist_rotate'>0 0 0 0 -0 0</pose>
        <inertial>
          <pose>0.021631 0 0.01141 0 -0 1.5708</pose>
          <mass>0.072885</mass>
          <inertia>
            <ixx>2.537e-05</ixx>
            <ixy>0</ixy>
            <ixz>0</ixz>
            <iyy>1.836e-05</iyy>
            <iyz>4.34e-07</iyz>
            <izz>1.674e-05</izz>
          </inertia>
        </inertial>
        <collision name='locobot/gripper_link_collision'>
          <pose>-0.02 0 0 0 -0 1.5708</pose>
          <geometry>
            <mesh>
              <scale>0.001 0.001 0.001</scale>
              <uri>/home/david/catkin_ws/src/locobot_simulation_david/meshes/mobile_wx250s_meshes/mobile_wx250s_7_gripper.stl</uri>
            </mesh>
          </geometry>
          <surface>
            <contact>
              <ode/>
            </contact>
            <friction>
              <ode/>
              <torsional>
                <ode/>
              </torsional>
            </friction>
            <bounce/>
          </surface>
          <max_contacts>10</max_contacts>
        </collision>
        <visual name='locobot/gripper_link_visual'>
          <pose>-0.02 0 0 0 -0 1.5708</pose>
          <geometry>
            <mesh>
              <scale>0.001 0.001 0.001</scale>
              <uri>/home/david/catkin_ws/src/locobot_simulation_david/meshes/mobile_wx250s_meshes/mobile_wx250s_7_gripper.stl</uri>
            </mesh>
          </geometry>
          <material>
            <script>
              <name>Custom/Interbotix</name>
              <uri>file://media/materials/scripts/gazebo.material</uri>
            </script>
          </material>
        </visual>
        <velocity_decay>
          <linear>0.01</linear>
          <angular>0.01</angular>
        </velocity_decay>
        <self_collide>0</self_collide>
        <enable_wind>0</enable_wind>
        <kinematic>0</kinematic>
      </link>
      <joint name='ee_arm' type='revolute'>
        <pose relative_to='locobot/gripper_link'>0.043 0 0 0 -0 0</pose>
        <parent>locobot/gripper_link</parent>
        <child>locobot/ee_arm_link</child>
        <axis>
          <limit>
            <lower>0</lower>
            <upper>0</upper>
          </limit>
          <dynamics>
            <damping>0</damping>
            <friction>0</friction>
            <spring_reference>0</spring_reference>
            <spring_stiffness>0</spring_stiffness>
          </dynamics>
          <xyz>0 0 1</xyz>
        </axis>
        <physics>
          <ode>
            <limit>
              <cfm>0</cfm>
              <erp>0.2</erp>
            </limit>
          </ode>
        </physics>
      </joint>
      <link name='locobot/ee_arm_link'>
        <pose relative_to='ee_arm'>0 0 0 0 -0 0</pose>
        <inertial>
          <pose>0 0 0 0 -0 0</pose>
          <mass>0.001</mass>
          <inertia>
            <ixx>0.001</ixx>
            <ixy>0</ixy>
            <ixz>0</ixz>
            <iyy>0.001</iyy>
            <iyz>0</iyz>
            <izz>0.001</izz>
          </inertia>
        </inertial>
        <self_collide>0</self_collide>
        <enable_wind>0</enable_wind>
        <kinematic>0</kinematic>
      </link>
      <joint name='ar_tag' type='revolute'>
        <pose relative_to='locobot/ee_arm_link'>-0.017 0 0.04155 0 -0 0</pose>
        <parent>locobot/ee_arm_link</parent>
        <child>locobot/ar_tag_link</child>
        <axis>
          <limit>
            <lower>0</lower>
            <upper>0</upper>
          </limit>
          <dynamics>
            <damping>0</damping>
            <friction>0</friction>
            <spring_reference>0</spring_reference>
            <spring_stiffness>0</spring_stiffness>
          </dynamics>
          <xyz>0 0 1</xyz>
        </axis>
        <physics>
          <ode>
            <limit>
              <cfm>0</cfm>
              <erp>0.2</erp>
            </limit>
          </ode>
        </physics>
      </joint>
      <link name='locobot/ar_tag_link'>
        <pose relative_to='ar_tag'>0 0 0 0 -0 0</pose>
        <inertial>
          <pose>0 0 -0.00315 0 -0 0</pose>
          <mass>0.016507</mass>
          <inertia>
            <ixx>3.084e-06</ixx>
            <ixy>0</ixy>
            <ixz>0</ixz>
            <iyy>3.084e-06</iyy>
            <iyz>0</iyz>
            <izz>6.059e-06</izz>
          </inertia>
        </inertial>
        <collision name='locobot/ar_tag_link_collision'>
          <pose>0 0 0 0 -0 0</pose>
          <geometry>
            <mesh>
              <scale>0.001 0.001 0.001</scale>
              <uri>/home/david/catkin_ws/src/locobot_simulation_david/meshes/mobile_wx250s_meshes/mobile_wx250s_11_ar_tag.stl</uri>
            </mesh>
          </geometry>
          <surface>
            <contact>
              <ode/>
            </contact>
            <friction>
              <ode/>
              <torsional>
                <ode/>
              </torsional>
            </friction>
            <bounce/>
          </surface>
          <max_contacts>10</max_contacts>
        </collision>
        <visual name='locobot/ar_tag_link_visual'>
          <pose>0 0 0 0 -0 0</pose>
          <geometry>
            <mesh>
              <scale>0.001 0.001 0.001</scale>
              <uri>/home/david/catkin_ws/src/locobot_simulation_david/meshes/mobile_wx250s_meshes/mobile_wx250s_11_ar_tag.stl</uri>
            </mesh>
          </geometry>
          <material>
            <script>
              <name>Custom/Interbotix</name>
              <uri>file://media/materials/scripts/gazebo.material</uri>
            </script>
          </material>
        </visual>
        <self_collide>0</self_collide>
        <enable_wind>0</enable_wind>
        <kinematic>0</kinematic>
      </link>
      <joint name='gripper' type='revolute'>
        <pose relative_to='locobot/ee_arm_link'>0.0055 0 0 0 -0 0</pose>
        <parent>locobot/ee_arm_link</parent>
        <child>locobot/gripper_prop_link</child>
        <axis>
          <xyz>1 0 0</xyz>
          <limit>
            <effort>1</effort>
            <velocity>3.14159</velocity>
            <lower>-1e+16</lower>
            <upper>1e+16</upper>
          </limit>
          <dynamics>
            <damping>0</damping>
            <friction>0.1</friction>
            <spring_reference>0</spring_reference>
            <spring_stiffness>0</spring_stiffness>
          </dynamics>
        </axis>
      </joint>
      <link name='locobot/gripper_prop_link'>
        <pose relative_to='gripper'>0 0 0 0 -0 0</pose>
        <inertial>
          <pose>0.000846 -2e-06 4.2e-05 0 -0 1.5708</pose>
          <mass>0.00434</mass>
          <inertia>
            <ixx>5.923e-07</ixx>
            <ixy>0</ixy>
            <ixz>3.195e-07</ixz>
            <iyy>1.1156e-06</iyy>
            <iyz>-4e-10</iyz>
            <izz>5.743e-07</izz>
          </inertia>
        </inertial>
        <collision name='locobot/gripper_prop_link_collision'>
          <pose>-0.0685 0 0 0 -0 1.5708</pose>
          <geometry>
            <mesh>
              <scale>0.001 0.001 0.001</scale>
              <uri>/home/david/catkin_ws/src/locobot_simulation_david/meshes/mobile_wx250s_meshes/mobile_wx250s_8_gripper_prop.stl</uri>
            </mesh>
          </geometry>
          <surface>
            <contact>
              <ode/>
            </contact>
            <friction>
              <ode/>
              <torsional>
                <ode/>
              </torsional>
            </friction>
            <bounce/>
          </surface>
          <max_contacts>10</max_contacts>
        </collision>
        <visual name='locobot/gripper_prop_link_visual'>
          <pose>-0.0685 0 0 0 -0 1.5708</pose>
          <geometry>
            <mesh>
              <scale>0.001 0.001 0.001</scale>
              <uri>/home/david/catkin_ws/src/locobot_simulation_david/meshes/mobile_wx250s_meshes/mobile_wx250s_8_gripper_prop.stl</uri>
            </mesh>
          </geometry>
          <material>
            <script>
              <name>Custom/Interbotix</name>
              <uri>file://media/materials/scripts/gazebo.material</uri>
            </script>
          </material>
        </visual>
        <velocity_decay>
          <linear>0.01</linear>
          <angular>0.01</angular>
        </velocity_decay>
        <self_collide>0</self_collide>
        <enable_wind>0</enable_wind>
        <kinematic>0</kinematic>
      </link>
      <joint name='gripper_bar' type='revolute'>
        <pose relative_to='locobot/ee_arm_link'>0 0 0 0 -0 0</pose>
        <parent>locobot/ee_arm_link</parent>
        <child>locobot/gripper_bar_link</child>
        <axis>
          <limit>
            <lower>0</lower>
            <upper>0</upper>
          </limit>
          <dynamics>
            <damping>0</damping>
            <friction>0</friction>
            <spring_reference>0</spring_reference>
            <spring_stiffness>0</spring_stiffness>
          </dynamics>
          <xyz>0 0 1</xyz>
        </axis>
        <physics>
          <ode>
            <limit>
              <cfm>0</cfm>
              <erp>0.2</erp>
            </limit>
          </ode>
        </physics>
      </joint>
      <link name='locobot/gripper_bar_link'>
        <pose relative_to='gripper_bar'>0 0 0 0 -0 0</pose>
        <inertial>
          <pose>0.009687 1e-06 0.004962 0 -0 1.5708</pose>
          <mass>0.034199</mass>
          <inertia>
            <ixx>7.4125e-06</ixx>
            <ixy>-8e-10</ixy>
            <ixz>-6e-10</ixz>
            <iyy>2.843e-05</iyy>
            <iyz>-1.3889e-06</iyz>
            <izz>2.86e-05</izz>
          </inertia>
        </inertial>
        <collision name='locobot/gripper_bar_link_collision'>
          <pose>-0.063 0 0 0 -0 1.5708</pose>
          <geometry>
            <mesh>
              <scale>0.001 0.001 0.001</scale>
              <uri>/home/david/catkin_ws/src/locobot_simulation_david/meshes/mobile_wx250s_meshes/mobile_wx250s_9_gripper_bar.stl</uri>
            </mesh>
          </geometry>
          <surface>
            <contact>
              <ode/>
            </contact>
            <friction>
              <ode/>
              <torsional>
                <ode/>
              </torsional>
            </friction>
            <bounce/>
          </surface>
          <max_contacts>10</max_contacts>
        </collision>
        <visual name='locobot/gripper_bar_link_visual'>
          <pose>-0.063 0 0 0 -0 1.5708</pose>
          <geometry>
            <mesh>
              <scale>0.001 0.001 0.001</scale>
              <uri>/home/david/catkin_ws/src/locobot_simulation_david/meshes/mobile_wx250s_meshes/mobile_wx250s_9_gripper_bar.stl</uri>
            </mesh>
          </geometry>
          <material>
            <script>
              <name>Custom/Interbotix</name>
              <uri>file://media/materials/scripts/gazebo.material</uri>
            </script>
          </material>
        </visual>
        <self_collide>0</self_collide>
        <enable_wind>0</enable_wind>
        <kinematic>0</kinematic>
      </link>
      <joint name='ee_bar' type='revolute'>
        <pose relative_to='locobot/gripper_bar_link'>0.023 0 0 0 -0 0</pose>
        <parent>locobot/gripper_bar_link</parent>
        <child>locobot/fingers_link</child>
        <axis>
          <limit>
            <lower>0</lower>
            <upper>0</upper>
          </limit>
          <dynamics>
            <damping>0</damping>
            <friction>0</friction>
            <spring_reference>0</spring_reference>
            <spring_stiffness>0</spring_stiffness>
          </dynamics>
          <xyz>0 0 1</xyz>
        </axis>
        <physics>
          <ode>
            <limit>
              <cfm>0</cfm>
              <erp>0.2</erp>
            </limit>
          </ode>
        </physics>
      </joint>
      <link name='locobot/fingers_link'>
        <pose relative_to='ee_bar'>0 0 0 0 -0 0</pose>
        <inertial>
          <pose>0 0 0 0 -0 0</pose>
          <mass>0.001</mass>
          <inertia>
            <ixx>0.001</ixx>
            <ixy>0</ixy>
            <ixz>0</ixz>
            <iyy>0.001</iyy>
            <iyz>0</iyz>
            <izz>0.001</izz>
          </inertia>
        </inertial>
        <self_collide>0</self_collide>
        <enable_wind>0</enable_wind>
        <kinematic>0</kinematic>
      </link>
      <joint name='ee_gripper' type='revolute'>
        <pose relative_to='locobot/fingers_link'>0.027575 0 0 0 -0 0</pose>
        <parent>locobot/fingers_link</parent>
        <child>locobot/ee_gripper_link</child>
        <axis>
          <limit>
            <lower>0</lower>
            <upper>0</upper>
          </limit>
          <dynamics>
            <damping>0</damping>
            <friction>0</friction>
            <spring_reference>0</spring_reference>
            <spring_stiffness>0</spring_stiffness>
          </dynamics>
          <xyz>0 0 1</xyz>
        </axis>
        <physics>
          <ode>
            <limit>
              <cfm>0</cfm>
              <erp>0.2</erp>
            </limit>
          </ode>
        </physics>
      </joint>
      <link name='locobot/ee_gripper_link'>
        <pose relative_to='ee_gripper'>0 0 0 0 -0 0</pose>
        <inertial>
          <pose>0 0 0 0 -0 0</pose>
          <mass>0.001</mass>
          <inertia>
            <ixx>0.001</ixx>
            <ixy>0</ixy>
            <ixz>0</ixz>
            <iyy>0.001</iyy>
            <iyz>0</iyz>
            <izz>0.001</izz>
          </inertia>
        </inertial>
        <self_collide>0</self_collide>
        <enable_wind>0</enable_wind>
        <kinematic>0</kinematic>
      </link>
      <joint name='left_finger' type='prismatic'>
        <pose relative_to='locobot/fingers_link'>0 0 0 0 -0 0</pose>
        <parent>locobot/fingers_link</parent>
        <child>locobot/left_finger_link</child>
        <axis>
          <xyz>0 1 0</xyz>
          <limit>
            <lower>0.015</lower>
            <upper>0.037</upper>
            <effort>5</effort>
            <velocity>1</velocity>
          </limit>
          <dynamics>
            <damping>0</damping>
            <friction>0.1</friction>
            <spring_reference>0</spring_reference>
            <spring_stiffness>0</spring_stiffness>
          </dynamics>
        </axis>
      </joint>
      <link name='locobot/left_finger_link'>
        <pose relative_to='left_finger'>0 0 0 0 -0 0</pose>
        <inertial>
          <pose>0.013816 0 0 0 0 -1.5708</pose>
          <mass>0.016246</mass>
          <inertia>
            <ixx>4.731e-06</ixx>
            <ixy>-4.56e-07</ixy>
            <ixz>0</ixz>
            <iyy>1.5506e-06</iyy>
            <iyz>0</iyz>
            <izz>3.7467e-06</izz>
          </inertia>
        </inertial>
        <collision name='locobot/left_finger_link_collision'>
          <pose>0 0.005 0 0 -0 3.14159</pose>
          <geometry>
            <mesh>
              <scale>0.001 0.001 0.001</scale>
              <uri>/home/david/catkin_ws/src/locobot_simulation_david/meshes/mobile_wx250s_meshes/mobile_wx250s_10_gripper_finger.stl</uri>
            </mesh>
          </geometry>
          <surface>
            <contact>
              <ode/>
            </contact>
            <friction>
              <ode/>
              <torsional>
                <ode/>
              </torsional>
            </friction>
            <bounce/>
          </surface>
          <max_contacts>10</max_contacts>
        </collision>
        <visual name='locobot/left_finger_link_visual'>
          <pose>0 0.005 0 0 -0 3.14159</pose>
          <geometry>
            <mesh>
              <scale>0.001 0.001 0.001</scale>
              <uri>/home/david/catkin_ws/src/locobot_simulation_david/meshes/mobile_wx250s_meshes/mobile_wx250s_10_gripper_finger.stl</uri>
            </mesh>
          </geometry>
          <material>
            <script>
              <name>Custom/Interbotix</name>
              <uri>file://media/materials/scripts/gazebo.material</uri>
            </script>
          </material>
        </visual>
        <velocity_decay>
          <linear>0.01</linear>
          <angular>0.01</angular>
        </velocity_decay>
        <self_collide>0</self_collide>
        <enable_wind>0</enable_wind>
        <kinematic>0</kinematic>
      </link>
      <joint name='right_finger' type='prismatic'>
        <pose relative_to='locobot/fingers_link'>0 0 0 0 -0 0</pose>
        <parent>locobot/fingers_link</parent>
        <child>locobot/right_finger_link</child>
        <axis>
          <xyz>0 1 0</xyz>
          <limit>
            <lower>-0.037</lower>
            <upper>-0.015</upper>
            <effort>5</effort>
            <velocity>1</velocity>
          </limit>
          <dynamics>
            <damping>0</damping>
            <friction>0.1</friction>
            <spring_reference>0</spring_reference>
            <spring_stiffness>0</spring_stiffness>
          </dynamics>
        </axis>
      </joint>
      <link name='locobot/right_finger_link'>
        <pose relative_to='right_finger'>0 0 0 0 -0 0</pose>
        <inertial>
          <pose>0.013816 0 0 3.14159 -0 -1.5708</pose>
          <mass>0.016246</mass>
          <inertia>
            <ixx>4.731e-06</ixx>
            <ixy>4.56e-07</ixy>
            <ixz>0</ixz>
            <iyy>1.5506e-06</iyy>
            <iyz>0</iyz>
            <izz>3.7467e-06</izz>
          </inertia>
        </inertial>
        <collision name='locobot/right_finger_link_collision'>
          <pose>0 -0.005 0 3.14159 -0 3.14159</pose>
          <geometry>
            <mesh>
              <scale>0.001 0.001 0.001</scale>
              <uri>/home/david/catkin_ws/src/locobot_simulation_david/meshes/mobile_wx250s_meshes/mobile_wx250s_10_gripper_finger.stl</uri>
            </mesh>
          </geometry>
          <surface>
            <contact>
              <ode/>
            </contact>
            <friction>
              <ode/>
              <torsional>
                <ode/>
              </torsional>
            </friction>
            <bounce/>
          </surface>
          <max_contacts>10</max_contacts>
        </collision>
        <visual name='locobot/right_finger_link_visual'>
          <pose>0 -0.005 0 3.14159 -0 3.14159</pose>
          <geometry>
            <mesh>
              <scale>0.001 0.001 0.001</scale>
              <uri>/home/david/catkin_ws/src/locobot_simulation_david/meshes/mobile_wx250s_meshes/mobile_wx250s_10_gripper_finger.stl</uri>
            </mesh>
          </geometry>
          <material>
            <script>
              <name>Custom/Interbotix</name>
              <uri>file://media/materials/scripts/gazebo.material</uri>
            </script>
          </material>
        </visual>
        <velocity_decay>
          <linear>0.01</linear>
          <angular>0.01</angular>
        </velocity_decay>
        <self_collide>0</self_collide>
        <enable_wind>0</enable_wind>
        <kinematic>0</kinematic>
      </link>
      <joint name='battery' type='revolute'>
        <pose relative_to='locobot/plate_link'>-0.007 0 0.0125 0 -0 0</pose>
        <parent>locobot/plate_link</parent>
        <child>locobot/battery_link</child>
        <axis>
          <limit>
            <lower>0</lower>
            <upper>0</upper>
          </limit>
          <dynamics>
            <damping>0</damping>
            <friction>0</friction>
            <spring_reference>0</spring_reference>
            <spring_stiffness>0</spring_stiffness>
          </dynamics>
          <xyz>0 0 1</xyz>
        </axis>
        <physics>
          <ode>
            <limit>
              <cfm>0</cfm>
              <erp>0.2</erp>
            </limit>
          </ode>
        </physics>
      </joint>
      <link name='locobot/battery_link'>
        <pose relative_to='battery'>0 0 0 0 -0 0</pose>
        <inertial>
          <pose>0 0 0.016 0 -0 0</pose>
          <mass>1.194</mass>
          <inertia>
            <ixx>0.004312</ixx>
            <ixy>0</ixy>
            <ixz>0</ixz>
            <iyy>0.001908</iyy>
            <iyz>0</iyz>
            <izz>0.006017</izz>
          </inertia>
        </inertial>
        <collision name='locobot/battery_link_collision'>
          <pose>0 0 0 0 -0 0</pose>
          <geometry>
            <mesh>
              <scale>0.001 0.001 0.001</scale>
              <uri>/home/david/catkin_ws/src/locobot_simulation_david/meshes/locobot_meshes/locobot_battery.stl</uri>
            </mesh>
          </geometry>
          <surface>
            <contact>
              <ode/>
            </contact>
            <friction>
              <ode/>
              <torsional>
                <ode/>
              </torsional>
            </friction>
            <bounce/>
          </surface>
          <max_contacts>10</max_contacts>
        </collision>
        <visual name='locobot/battery_link_visual'>
          <pose>0 0 0 0 -0 0</pose>
          <geometry>
            <mesh>
              <scale>0.001 0.001 0.001</scale>
              <uri>/home/david/catkin_ws/src/locobot_simulation_david/meshes/locobot_meshes/locobot_battery.stl</uri>
            </mesh>
          </geometry>
          <material>
            <script>
              <name>Gazebo/Grey</name>
              <uri>file://media/materials/scripts/gazebo.material</uri>
            </script>
          </material>
        </visual>
        <self_collide>0</self_collide>
        <enable_wind>0</enable_wind>
        <kinematic>0</kinematic>
      </link>
      <joint name='wheel_left_joint' type='revolute'>
        <pose relative_to='locobot/base_footprint'>0 0.115 0.0352 -1.5708 0 0</pose>
        <parent>locobot/base_footprint</parent>
        <child>locobot/wheel_left_link</child>
        <axis>
          <xyz>0 0 1</xyz>
          <limit>
            <lower>-1e+16</lower>
            <upper>1e+16</upper>
          </limit>
          <dynamics>
            <spring_reference>0</spring_reference>
            <spring_stiffness>0</spring_stiffness>
          </dynamics>
        </axis>
      </joint>
      <link name='locobot/wheel_left_link'>
        <pose relative_to='wheel_left_joint'>0 0 0 0 -0 0</pose>
        <inertial>
          <pose>0 0 0 0 -0 0</pose>
          <mass>0.01</mass>
          <inertia>
            <ixx>0.001</ixx>
            <ixy>0</ixy>
            <ixz>0</ixz>
            <iyy>0.001</iyy>
            <iyz>0</iyz>
            <izz>0.001</izz>
          </inertia>
        </inertial>
        <collision name='locobot/wheel_left_link_collision'>
          <pose>0 0 0 0 -0 0</pose>
          <geometry>
            <cylinder>
              <length>0.0206</length>
              <radius>0.0352</radius>
            </cylinder>
          </geometry>
          <surface>
            <contact>
              <ode>
                <kp>1e+06</kp>
                <kd>100</kd>
                <max_vel>1</max_vel>
                <min_depth>0.001</min_depth>
              </ode>
            </contact>
            <friction>
              <ode>
                <mu>1</mu>
                <mu2>1</mu2>
              </ode>
              <torsional>
                <ode/>
              </torsional>
            </friction>
            <bounce/>
          </surface>
          <max_contacts>10</max_contacts>
        </collision>
        <visual name='locobot/wheel_left_link_visual'>
          <pose>0 0 0 0 -0 0</pose>
          <geometry>
            <mesh>
              <scale>1 1 1</scale>
              <uri>/home/david/catkin_ws/src/locobot_simulation_david/meshes/locobot_meshes/locobot_wheel.dae</uri>
            </mesh>
          </geometry>
        </visual>
        <self_collide>0</self_collide>
        <enable_wind>0</enable_wind>
        <kinematic>0</kinematic>
      </link>
      <joint name='wheel_right_joint' type='revolute'>
        <pose relative_to='locobot/base_footprint'>0 -0.115 0.0352 -1.5708 0 0</pose>
        <parent>locobot/base_footprint</parent>
        <child>locobot/wheel_right_link</child>
        <axis>
          <xyz>0 0 1</xyz>
          <limit>
            <lower>-1e+16</lower>
            <upper>1e+16</upper>
          </limit>
          <dynamics>
            <spring_reference>0</spring_reference>
            <spring_stiffness>0</spring_stiffness>
          </dynamics>
        </axis>
      </joint>
      <link name='locobot/wheel_right_link'>
        <pose relative_to='wheel_right_joint'>0 0 0 0 -0 0</pose>
        <inertial>
          <pose>0 0 0 0 -0 0</pose>
          <mass>0.01</mass>
          <inertia>
            <ixx>0.001</ixx>
            <ixy>0</ixy>
            <ixz>0</ixz>
            <iyy>0.001</iyy>
            <iyz>0</iyz>
            <izz>0.001</izz>
          </inertia>
        </inertial>
        <collision name='locobot/wheel_right_link_collision'>
          <pose>0 0 0 0 -0 0</pose>
          <geometry>
            <cylinder>
              <length>0.0206</length>
              <radius>0.035</radius>
            </cylinder>
          </geometry>
          <surface>
            <contact>
              <ode>
                <kp>1e+06</kp>
                <kd>100</kd>
                <max_vel>1</max_vel>
                <min_depth>0.001</min_depth>
              </ode>
            </contact>
            <friction>
              <ode>
                <mu>1</mu>
                <mu2>1</mu2>
              </ode>
              <torsional>
                <ode/>
              </torsional>
            </friction>
            <bounce/>
          </surface>
          <max_contacts>10</max_contacts>
        </collision>
        <visual name='locobot/wheel_right_link_visual'>
          <pose>0 0 0 0 -0 0</pose>
          <geometry>
            <mesh>
              <scale>1 1 1</scale>
              <uri>/home/david/catkin_ws/src/locobot_simulation_david/meshes/locobot_meshes/locobot_wheel.dae</uri>
            </mesh>
          </geometry>
        </visual>
        <self_collide>0</self_collide>
        <enable_wind>0</enable_wind>
        <kinematic>0</kinematic>
      </link>
      <plugin name='gazebo_ros_control' filename='libgazebo_ros_control.so'>
        <robotSimType>gazebo_ros_control/DefaultRobotHWSim</robotSimType>
        <legacyModeNS>1</legacyModeNS>
        <robotNamespace>/locobot/</robotNamespace>
      </plugin>
      <plugin name='differential_drive_controller' filename='libgazebo_ros_diff_drive.so'>
        <alwaysOn>1</alwaysOn>
        <legacyMode>0</legacyMode>
        <updateRate>40</updateRate>
        <leftJoint>wheel_left_joint</leftJoint>
        <rightJoint>wheel_right_joint</rightJoint>
        <wheelSeparation>0.230</wheelSeparation>
        <wheelDiameter>0.070</wheelDiameter>
        <wheelTorque>1.0</wheelTorque>
        <wheelAcceleration>0</wheelAcceleration>
        <commandTopic>mobile_base/commands/velocity</commandTopic>
        <odometryTopic>odom</odometryTopic>
        <odometryFrame>odom</odometryFrame>
        <robotBaseFrame>base_footprint</robotBaseFrame>
        <publishWheelJointState>1</publishWheelJointState>
        <rosDebugLevel>na</rosDebugLevel>
        <publishWheelTF>0</publishWheelTF>
        <publishOdomTF>0</publishOdomTF>
        <odometrySource>world</odometrySource>
        <publishTf>1</publishTf>
        <robotNamespace>/locobot/</robotNamespace>
      </plugin>
      <plugin name='p3d_base_controller' filename='libgazebo_ros_p3d.so'>
        <alwaysOn>1</alwaysOn>
        <updateRate>100.0</updateRate>
        <topicName>base/absolute_position</topicName>
        <gaussianNoise>0</gaussianNoise>
        <frameName>map</frameName>
        <xyzOffsets>0 0 0</xyzOffsets>
        <rpyOffsets>0 0 0</rpyOffsets>
        <robotNamespace>/locobot/</robotNamespace>
        <bodyName>locobot/base_footprint</bodyName>
        <xyzOffset>0 0 0.0102</xyzOffset>
        <rpyOffset>0 -0 0</rpyOffset>
        <ignition::corrected_offsets>1</ignition::corrected_offsets>
      </plugin>
      <frame name='caster_back_joint' attached_to='locobot/base_link'>
        <pose>-0.135 0 0.009 -1.5708 0 0</pose>
      </frame>
      <frame name='locobot/caster_back_link' attached_to='caster_back_joint'/>
      <frame name='caster_front_joint' attached_to='locobot/base_link'>
        <pose>0.115 0 0.007 -1.5708 0 0</pose>
      </frame>
      <frame name='locobot/caster_front_link' attached_to='caster_front_joint'/>
      <frame name='cliff_sensor_front_joint' attached_to='locobot/base_link'>
        <pose>0.156 0 0.0214 3.14159 1.57079 3.14159</pose>
      </frame>
      <frame name='locobot/cliff_sensor_front_link' attached_to='cliff_sensor_front_joint'/>
      <frame name='cliff_sensor_left_joint' attached_to='locobot/base_link'>
        <pose>0.08734 0.13601 0.0214 3.14159 1.57079 3.14159</pose>
      </frame>
      <frame name='locobot/cliff_sensor_left_link' attached_to='cliff_sensor_left_joint'/>
      <frame name='cliff_sensor_right_joint' attached_to='locobot/base_link'>
        <pose>0.085 -0.13601 0.0214 3.14159 1.57079 3.14159</pose>
      </frame>
      <frame name='locobot/cliff_sensor_right_link' attached_to='cliff_sensor_right_joint'/>
      <frame name='gyro_joint' attached_to='locobot/base_link'>
        <pose>0.056 0.062 0.0202 0 -0 0</pose>
      </frame>
      <frame name='locobot/gyro_link' attached_to='gyro_joint'/>
      <frame name='base_joint' attached_to='locobot/base_footprint'>
        <pose>0 0 0.0102 0 -0 0</pose>
      </frame>
      <frame name='locobot/base_link' attached_to='base_joint'/>
      <frame name='ros_logical_camera' attached_to='locobot/tilt_link'>
        <pose>0.05318 0.0175 9e-06 0 -0 0</pose>
      </frame>
      <frame name='locobot/ros_logical_camera' attached_to='ros_logical_camera'/>
      <pose>0 0 0 0 -0 0</pose>
    </model>
  </world>
</sdf>
